<?xml version="1.0" ?>
<robot name="picarx">
  <link name="base_footprint" />

  <joint name="base_footprint_joint" type="fixed">
    <parent link="base_footprint" />
    <child link="base_link" />
  </joint>
  <joint name="joint_wheel_left" type="continuous">
    <parent link="base_link"/>
    <child link="right_wheel"/>
    <origin rpy="1.5708  0      0" xyz="-0.01949  0.06926  0.03808"/>
    <axis xyz="0  0  1"/>
    <limit effort="1.0" lower="-1.79769e+308" upper="1.79769e+308" velocity="1.0"/>
  </joint>
  <joint name="base_link_JOINT_steer_fr" type="fixed">
    <parent link="base_link"/>
    <child link="picarx_steer_fr"/>
    <origin rpy="0  0  0" xyz="0.137   -0.04999  0.029"/>
  </joint>
  <joint name="joint_wheel_right" type="continuous">
    <parent link="base_link"/>
    <child link="left_wheel"/>
    <origin rpy="1.5708  0      0" xyz="-0.0195  -0.06925  0.03808"/>
    <axis xyz="0 0 1"/>
    <limit effort="1.0" lower="-1.79769e+308" upper="1.79769e+308" velocity="1.0"/>
  </joint>
  <joint name="picarx_steer_fr_JOINT_FrontRight" type="revolute">
    <parent link="picarx_steer_fr"/>
    <child link="picarx_WheelFrontLeft"/>
    <origin rpy="1.5708  0      0" xyz="0.00542 -0.01816  0.00908"/>
    <axis xyz="0  0  1"/>
    <limit effort="1.0" lower="-1.79769e+308" upper="1.79769e+308" velocity="1.0"/>
  </joint>
  <joint name="picarx_steer_fl_JOINT_FrontLeft" type="revolute">
    <parent link="picarx_steer_fl"/>
    <child link="picarx_WheelFrontRight"/>
    <origin rpy="1.5708  0      0" xyz="0.00542  0.01983  0.00908"/>
    <axis xyz="0  0  1"/>
    <limit effort="1.0" lower="-1.79769e+308" upper="1.79769e+308" velocity="1.0"/>
  </joint>
  <joint name="base_link_JOINT_steer_fl" type="fixed">
    <parent link="base_link"/>
    <child link="picarx_steer_fl"/>
    <origin rpy="0  0  0" xyz="0.137  0.049  0.029"/>
  </joint>
  <link name="base_link">
    <inertial>
      <mass value="1"/>
      <origin rpy="0  0  0" xyz="0  0  0"/>
      <inertia ixx="0.166667" ixy="0" ixz="0" iyy="0.166667" iyz="0" izz="0.166667"/>
    </inertial>
    <collision name="picarx_collision">
      <origin rpy="0  0  0" xyz="0     0     0.015"/>
      <geometry>
        <mesh filename="package://picarx_description/meshes/Chassis.dae" scale="1 1 1"/>
      </geometry>
    </collision>
    <visual name="picarx_visual">
      <origin rpy="0  0  0" xyz="0     0     0.015"/>
      <geometry>
        <mesh filename="package://picarx_description/meshes/Chassis.dae" scale="1 1 1"/>
      </geometry>
    </visual>
  </link>
  <link name="right_wheel">
    <inertial>
      <mass value="1"/>
      <origin rpy="0  0  0" xyz="0  0  0"/>
      <inertia ixx="0.166667" ixy="0" ixz="0" iyy="0.166667" iyz="0" izz="0.166667"/>
    </inertial>
    <collision name="picarx_collision">
      <origin rpy="0  0  0" xyz="0  0  0"/>
      <geometry>
        <mesh filename="package://picarx_description/meshes/WheelRearLeft.dae" scale="1 1 1"/>
      </geometry>
    </collision>
    <visual name="picarx_visual">
      <origin rpy="0  0  0" xyz="0  0  0"/>
      <geometry>
        <mesh filename="package://picarx_description/meshes/WheelRearLeft.dae" scale="1 1 1"/>
      </geometry>
    </visual>
  </link>
  <link name="left_wheel">
    <inertial>
      <mass value="1"/>
      <origin rpy="0  0  0" xyz="0  0  0"/>
      <inertia ixx="0.166667" ixy="0" ixz="0" iyy="0.166667" iyz="0" izz="0.166667"/>
    </inertial>
    <collision name="picarx_collision">
      <origin rpy="0  0  0" xyz="0  0  0"/>
      <geometry>
        <mesh filename="package://picarx_description/meshes/WheelRearRight.dae" scale="1 1 1"/>
      </geometry>
    </collision>
    <visual name="picarx_visual">
      <origin rpy="0  0  0" xyz="0  0  0"/>
      <geometry>
        <mesh filename="package://picarx_description/meshes/WheelRearRight.dae" scale="1 1 1"/>
      </geometry>
    </visual>
  </link>
  <link name="picarx_WheelFrontLeft">
    <inertial>
      <mass value="1"/>
      <origin rpy="0  0  0" xyz="0  0  0"/>
      <inertia ixx="0.166667" ixy="0" ixz="0" iyy="0.166667" iyz="0" izz="0.166667"/>
    </inertial>
    <collision name="picarx_collision">
      <origin rpy="0  0  0" xyz="0  0  0"/>
      <geometry>
        <mesh filename="package://picarx_description/meshes/WheelFrontLeft.dae" scale="1 1 1"/>
      </geometry>
    </collision>
    <visual name="picarx_visual">
      <origin rpy="0  0  0" xyz="0  0  0"/>
      <geometry>
        <mesh filename="package://picarx_description/meshes/WheelFrontLeft.dae" scale="1 1 1"/>
      </geometry>
    </visual>
  </link>
  <link name="picarx_WheelFrontRight">
    <inertial>
      <mass value="1"/>
      <origin rpy="0  0  0" xyz="0  0  0"/>
      <inertia ixx="0.166667" ixy="0" ixz="0" iyy="0.166667" iyz="0" izz="0.166667"/>
    </inertial>
    <collision name="picarx_collision">
      <origin rpy="0  0  0" xyz="0  0  0"/>
      <geometry>
        <mesh filename="package://picarx_description/meshes/WheelFrontRight.dae" scale="1 1 1"/>
      </geometry>
    </collision>
    <visual name="picarx_visual">
      <origin rpy="0  0  0" xyz="0  0  0"/>
      <geometry>
        <mesh filename="package://picarx_description/meshes/WheelFrontRight.dae" scale="1 1 1"/>
      </geometry>
    </visual>
  </link>
  <link name="picarx_steer_fl">
    <inertial>
      <mass value="1"/>
      <origin rpy="0  0  0" xyz="0  0  0"/>
      <inertia ixx="0" ixy="0" ixz="0" iyy="0" iyz="0" izz="0"/>
    </inertial>
    <visual name="picarx_visual">
      <origin rpy="0  0  0" xyz="0  0  0"/>
      <geometry>
        <cylinder length="0.025" radius="0.005"/>
      </geometry>
    </visual>
  </link>
  <link name="picarx_steer_fr">
    <inertial>
      <mass value="1"/>
      <origin rpy="0  0  0" xyz="0  0  0"/>
      <inertia ixx="0" ixy="0" ixz="0" iyy="0" iyz="0" izz="0"/>
    </inertial>
    <visual name="picarx_visual">
      <origin rpy="0  0  0" xyz="0  0  0"/>
      <geometry>
        <cylinder length="0.025" radius="0.005"/>
      </geometry>
    </visual>
  </link>

  <transmission name="trans_right_wheel">
    <type>transmission_interface/SimpleTransmission</type>
    <joint name="joint_wheel_right">
      <hardwareInterface>hardware_interface/EffortJointInterface</hardwareInterface>
    </joint>
    <actuator name="motor_right_wheel">
      <mechanicalReduction>1</mechanicalReduction>
      <hardwareInterface>hardware_interface/EffortJointInterface</hardwareInterface>
    </actuator>
  </transmission>

  <transmission name="trans_left_wheel">
    <type>transmission_interface/SimpleTransmission</type>
    <joint name="joint_wheel_left">
      <hardwareInterface>hardware_interface/EffortJointInterface</hardwareInterface>
    </joint>
    <actuator name="motor_left_wheel">
      <mechanicalReduction>1</mechanicalReduction>
      <hardwareInterface>hardware_interface/EffortJointInterface</hardwareInterface>
    </actuator>
  </transmission>

  <gazebo>
    <plugin name="gazebo_ros_control" filename="libgazebo_ros_control.so">
      <robotNamespace>/picarx</robotNamespace>
    </plugin>
  </gazebo>
</robot>
